Workbook

Sheet Order
B2: MENU CA SÁNG | H2: CA CHIỀU | N2: Các bước thực hiện: | T2: Các bước thực hiện:
B3: Món chính | H3: Món chính | N3: B1: Chọn lần lượt menu ca sáng, ca chiều | T3: B1: Đưa trỏ chuột vào bảng dữ liệu
B4: Món phụ | H4: Món phụ | N4: B2: Chọn chi tiết "Món" - Ô C12 & ô I12 để lấy chi tiết nguyên liệu và số lượng order | T4: B2: Click "chuột phải" -> Pivot analys -> change data source -> chọn hết dữ liệu ở BẢNG PHỤ
B5: Món rau | H5: Món rau | K5: 91 | N5: B3: Copy value vào "BẢNG PHỤ - NGUYÊN LIỆU TỔNG HỢP" theo format bên dưới | T5: B3: Đưa trỏ chuột vào bảng dữ liệu --> click chuột phải -> refresh
B6: Mắm | E6: 5 | F6: 100 | H6: Mắm | N6: Lưu ý: | T6: Lưu ý:
B7: Món canh | E7: 15 | F7: 520 | H7: Món canh | J7: 87 | N7: Bảng phụ này được nhập tay và copy value từ " Bảng 1" và Bảng 2" | T7: Bảng ORDER này được chạy tự động từ "BẢNG PHỤ - NGUYÊN LIỆU TỔNG HỢP"
B8: Tráng miệng | E8: 4 | F8: 106 | H8: Tráng miệng | J8: 43 | N8: Cột "Nhà cung cấp" có thể phân loại nhiều item khác nhau để thuận tiện cho việc order | T8: Có thể thêm dòng ghi chú giao hàng ở cột Z
N9: Bảng này có thể in ra dán trên bảng thay vì viết tay
B11: CA SÁNG (BẢNG 1) | D11: Suất ăn DAV | E11: 580 | H11: CA CHIỀU (BẢNG 2) | J11: Suất ăn DAV | K11: 100 | N11: BẢNG PHỤ - NGUYÊN LIỆU TỔNG HỢP | T11: BẢNG ORDER NGÀY 06/07/2026
B12: Món | C12: Bí đao nấu tôm | D12: Suất ăn AVN | F12: 96 | H12: Món | I12: Đậu khuôn thịt bằm | J12: Suất ăn AVN
T13: Sum of Số lượng Order | U13: Column Labels
B14: NL Rau | C14: Định lượng (kg) / khay | D14: Khối lượng yêu cầu (kg) | E14: Lượng tồn (kg) | F14: Khối lượng cần đặt (kg) | H14: Row Labels | I14: Định lượng (kg) / khay | J14: Khối lượng yêu cầu (kg) | K14: Lượng tồn (kg) | L14: Khối lượng cần đặt (kg) | N14: Ca Nấu | O14: Nhà cung cấp | P14: Tên nguyên liệu | Q14: Số lượng Order | R14: Note | T14: Row Labels | U14: (blank) | V14: Grand Total | X14: Ghi chú
B15: Bí đao | C15: =IFERROR(VLOOKUP($C$12&$B15,'định lượng suất 25k'!$B:$J,9,0),0) -> 0.036764706 | D15: =C15*SUM($E$11:$E$12) -> 21.323529 | E15: 0 | F15: =D15-E15 -> 21.323529 | H15: NL Rau | I15: =IFERROR(VLOOKUP($I$12&H15,'định lượng suất 25k'!$B:$J,9,0),0) -> 0 | J15: =I15*SUM($K$11:$K$12) -> 0 | K15: 0 | L15: =J15-K15 -> 0 | T15: (blank)
B16: NL tươi sống | C16: =IFERROR(VLOOKUP($C$12&$B16,'định lượng suất 25k'!$B:$J,9,0),0) -> 0 | D16: =C16*SUM($E$11:$E$12) -> 0 | F16: =D16-E16 -> 0 | H16: Cà rốt | I16: =IFERROR(VLOOKUP($I$12&$H16,'định lượng suất 25k'!$B:$J,9,0),0) -> 0.016949153 | J16: =I16*SUM($K$11:$K$12) -> 1.6949153 | L16: =J16-K16 -> 1.6949153 | T16: Grand Total
B17: Tôm | C17: =IFERROR(VLOOKUP($C$12&$B17,'định lượng suất 25k'!$B:$J,9,0),0) -> 0.0037313433 | D17: =C17*SUM($E$11:$E$12) -> 2.1641791 | F17: =D17-E17 -> 2.1641791 | H17: Đậu khuôn | I17: =IFERROR(VLOOKUP($I$12&$H17,'định lượng suất 25k'!$B:$J,9,0),0) -> 1 | J17: =I17*SUM($K$11:$K$12) -> 100 | K17: 0 | L17: =J17-K17 -> 100
C18: =IFERROR(VLOOKUP($C$12&$B18,'định lượng suất 25k'!$B:$J,9,0),0) -> 0 | D18: =C18*SUM($E$11:$E$12) -> 0 | F18: =D18-E18 -> 0 | H18: Nấm mèo | I18: =IFERROR(VLOOKUP($I$12&$H18,'định lượng suất 25k'!$B:$J,9,0),0) -> 0.0016949153 | J18: =I18*SUM($K$11:$K$12) -> 0.16949153 | K18: 0 | L18: =J18-K18 -> 0.16949153
C19: =IFERROR(VLOOKUP($C$12&$B19,'định lượng suất 25k'!$B:$J,9,0),0) -> 0 | D19: =C19*SUM($E$11:$E$12) -> 0 | F19: =D19-E19 -> 0 | H19: NL tươi sống | I19: =IFERROR(VLOOKUP($I$12&$H19,'định lượng suất 25k'!$B:$J,9,0),0) -> 0 | J19: =I19*SUM($K$11:$K$12) -> 0 | K19: 0 | L19: =J19-K19 -> 0
C20: =IFERROR(VLOOKUP($C$12&$B20,'định lượng suất 25k'!$B:$J,9,0),0) -> 0 | D20: =C20*SUM($E$11:$E$12) -> 0 | F20: =D20-E20 -> 0 | H20: Thịt bằm | I20: =IFERROR(VLOOKUP($I$12&$H20,'định lượng suất 25k'!$B:$J,9,0),0) -> 0.01 | J20: =I20*SUM($K$11:$K$12) -> 1 | K20: 0 | L20: =J20-K20 -> 1
C21: =IFERROR(VLOOKUP($C$12&$B21,'định lượng suất 25k'!$B:$J,9,0),0) -> 0 | D21: =C21*SUM($E$11:$E$12) -> 0 | F21: =D21-E21 -> 0 | I21: =IFERROR(VLOOKUP($I$12&$H21,'định lượng suất 25k'!$B:$J,9,0),0) -> 0 | J21: =I21*SUM($K$11:$K$12) -> 0 | L21: =J21-K21 -> 0
C22: =IFERROR(VLOOKUP($C$12&$B22,'định lượng suất 25k'!$B:$J,9,0),0) -> 0 | D22: =C22*SUM($E$11:$E$12) -> 0 | F22: =D22-E22 -> 0 | I22: =IFERROR(VLOOKUP($I$12&$H22,'định lượng suất 25k'!$B:$J,9,0),0) -> 0 | J22: =I22*SUM($K$11:$K$12) -> 0 | K22: 0 | L22: =J22-K22 -> 0
C23: =IFERROR(VLOOKUP($C$12&$B23,'định lượng suất 25k'!$B:$J,9,0),0) -> 0 | D23: =C23*SUM($E$11:$E$12) -> 0 | E23: 0 | F23: =D23-E23 -> 0 | I23: =IFERROR(VLOOKUP($I$12&$H23,'định lượng suất 25k'!$B:$J,9,0),0) -> 0 | J23: =I23*SUM($K$11:$K$12) -> 0 | K23: 0 | L23: =J23-K23 -> 0
C24: =IFERROR(VLOOKUP($C$12&$B24,'định lượng suất 25k'!$B:$J,9,0),0) -> 0 | D24: =C24*SUM($E$11:$E$12) -> 0 | E24: 0 | F24: =D24-E24 -> 0 | I24: =IFERROR(VLOOKUP($I$12&$H24,'định lượng suất 25k'!$B:$J,9,0),0) -> 0 | J24: =I24*SUM($K$11:$K$12) -> 0 | K24: 0 | L24: =J24-K24 -> 0
C25: =IFERROR(VLOOKUP($C$12&$B25,'định lượng suất 25k'!$B:$J,9,0),0) -> 0 | D25: =C25*SUM($E$11:$E$12) -> 0 | F25: =D25-E25 -> 0 | I25: =IFERROR(VLOOKUP($I$12&$H25,'định lượng suất 25k'!$B:$J,9,0),0) -> 0 | J25: =I25*SUM($K$11:$K$12) -> 0 | K25: 0 | L25: =J25-K25 -> 0
C26: =IFERROR(VLOOKUP($C$12&$B26,'định lượng suất 25k'!$B:$J,9,0),0) -> 0 | D26: =C26*SUM($E$11:$E$12) -> 0 | E26: 0 | F26: =D26-E26 -> 0 | I26: =IFERROR(VLOOKUP($I$12&$H26,'định lượng suất 25k'!$B:$J,9,0),0) -> 0 | J26: =I26*SUM($K$11:$K$12) -> 0 | K26: 0 | L26: =J26-K26 -> 0
C27: =IFERROR(VLOOKUP($C$12&$B27,'định lượng suất 25k'!$B:$J,9,0),0) -> 0 | D27: =C27*SUM($E$11:$E$12) -> 0 | E27: 0 | F27: =D27-E27 -> 0 | I27: =IFERROR(VLOOKUP($I$12&$H27,'định lượng suất 25k'!$B:$J,9,0),0) -> 0 | J27: =I27*SUM($K$11:$K$12) -> 0 | K27: 0 | L27: =J27-K27 -> 0
C28: =IFERROR(VLOOKUP($C$12&$B28,'định lượng suất 25k'!$B:$J,9,0),0) -> 0 | D28: =C28*SUM($E$11:$E$12) -> 0 | E28: 0 | F28: =D28-E28 -> 0 | I28: =IFERROR(VLOOKUP($I$12&$H28,'định lượng suất 25k'!$B:$J,9,0),0) -> 0 | J28: =I28*SUM($K$11:$K$12) -> 0 | K28: 0 | L28: =J28-K28 -> 0
C29: =IFERROR(VLOOKUP($C$12&$B43,'định lượng suất 25k'!$B:$J,9,0),0) -> 0 | D29: =C29*SUM($E$11:$E$12) -> 0 | E29: 0 | F29: =D29-E29 -> 0 | I29: =IFERROR(VLOOKUP($I$12&$H29,'định lượng suất 25k'!$B:$J,9,0),0) -> 0 | J29: =I29*SUM($K$11:$K$12) -> 0 | K29: 0
X54: kg
X55: lát
X56: kg
X57: kg
X59: kg
X61: kg
X62: kg
X63: kg
X64: kg
X65: kg
X67: quả
X68: quả
... X85: kg

Sheet Calculation
C2: MENU DAV | J2: MENU AVN
C3: Thứ 2 | D3: Thứ 3 | E3: Thứ 4 | F3: Thứ 5 | G3: Thứ 6 | H3: Thứ 7 | J3: Thứ 2 | K3: Thứ 3 | L3: Thứ 4 | M3: Thứ 5 | N3: Thứ 6 | O3: Thứ 7
B4: Món chính | I4: Món chính
B5: Món phụ | I5: Món phụ
B6: Món rau | I6: Món rau
B7: Mắm | I7: Mắm
B8: Món canh | I8: Món canh
B9: Tráng miệng | I9: Tráng miệng
H10: 26793500
C11: 20
C13: Menu món nước | D13: Cost | M13: Menu món cơm | N13: Cost | AK13: =SUMIF(D13:AG13,">0") -> 0
B14: Món chính | C14: =C24 -> Bún thịt nướng | D14: =D25 -> 8210 | L14: Món chính | M14: =M24 -> Thịt kho sả ruốc | N14: =N25 -> 4705.1282
B15: Tráng miệng | C15: =M71 -> Trái cây | D15: =N72 -> 1620.9458 | L15: Món phụ | M15: =M34 -> Đậu khuôn thịt bằm | N15: =N35 -> 2840.678
D16: =SUM(D14:D15) -> 9830.9458 | L16: Món rau | M16: =M44 -> Rau muống xào tỏi | N16: =N45 -> 576
L17: Mắm | M17: =M51 -> Dưa món | N17: =N52 -> 540
L18: Món canh | M18: =M61 -> Bầu nấu tôm | N18: =N62 -> 783.33333
L19: Tráng miệng | M19: =M71 -> Trái cây | N19: =N72 -> 1620.9458
N20: =SUM(N14:N19) -> 11066.085
B23: Menu | C23: (All) | F23: Suất ăn DAV | G23: 300 | L23: Menu | M23: Món chính | P23: Suất ăn DAV | Q23: 52
B24: Món | C24: Bún thịt nướng | F24: Suất ăn AVN | L24: Món | M24: Thịt kho sả ruốc | P24: Suất ăn AVN
D25: =SUM(D27:D1048576) -> 8210 | J25: =SUM(J27:J1048576) -> 2283000 | N25: =SUM(N27:N31) -> 4705.1282 | T25: =SUM(T27:T31) -> 244666.67
B26: Row Labels | C26: Định lượng (kg) / khay | D26: Cost / khay | F26: Khối lượng yêu cầu (kg) | G26: Lượng tồn (kg) | H26: Khối lượng cần đặt (kg) | I26: Giá nhập (kg) | J26: Thành tiền | L26: Row Labels | M26: Định lượng (kg) / khay | N26: Cost / khay | P26: Khối lượng yêu cầu (kg) | Q26: Lượng tồn (kg) | R26: Khối lượng cần đặt (kg) | S26: Giá nhập (kg) | T26: Thành tiền
B27: Cà chua | C27: =IFERROR(VLOOKUP($C$24&$B27,'định lượng suất 25k'!$B:$J,9,0),0) -> 0 | D27: =IFERROR(VLOOKUP($C$24&$B27,'định lượng suất 25k'!$B:$K,10,0),0) -> 0 | F27: =C27*SUM($G$23:$G$24) -> 0 | G27: 0 | H27: =F27-G27 -> 0 | I27: =IFERROR(VLOOKUP($C$24&$B27,'định lượng suất 25k'!$B:$H,7,0),0) -> 0 | J27: =H27*I27 -> 0 | L27: Thịt nạc vai | M27: =IFERROR(VLOOKUP($M$24&$L27,'định lượng suất 25k'!$B:$J,9,0),0) -> 0.029487179 | N27: =IFERROR(VLOOKUP($M$24&$L27,'định lượng suất 25k'!$B:$K,10,0),0) -> 3243.5897 | P27: =M27*SUM($Q$23:$Q$24) -> 1.5333333 | R27: =P27-Q27 -> 1.5333333 | S27: =IFERROR(VLOOKUP($M$24&$L27,'định lượng suất 25k'!$B:$H,7,0),0) -> 110000 | T27: =R27*S27 -> 168666.67
B28: Hành lá | C28: =IFERROR(VLOOKUP($C$24&$B28,'định lượng suất 25k'!$B:$J,9,0),0) -> 0 | D28: =IFERROR(VLOOKUP($C$24&$B28,'định lượng suất 25k'!$B:$K,10,0),0) -> 0 | F28: =C28*SUM($G$23:$G$24) -> 0 | G28: 1 | H28: =F28-G28 -> -1 | I28: =IFERROR(VLOOKUP($C$24&$B28,'định lượng suất 25k'!$B:$H,7,0),0) -> 0 | J28: =H28*I28 -> 0 | L28: Sả | M28: =IFERROR(VLOOKUP($M$24&$L28,'định lượng suất 25k'!$B:$J,9,0),0) -> 0.0064102564 | N28: =IFERROR(VLOOKUP($M$24&$L28,'định lượng suất 25k'!$B:$K,10,0),0) -> 160.25641 | P28: =M28*SUM($Q$23:$Q$24) -> 0.33333333 | R28: =P28-Q28 -> 0.33333333 | S28: =IFERROR(VLOOKUP($M$24&$L28,'định lượng suất 25k'!$B:$H,7,0),0) -> 25000 | T28: =R28*S28 -> 8333.3333
B29: Nạc vai | C29: =IFERROR(VLOOKUP($C$24&$B29,'định lượng suất 25k'!$B:$J,9,0),0) -> 0.075 | D29: =IFERROR(VLOOKUP($C$24&$B29,'định lượng suất 25k'!$B:$K,10,0),0) -> 6750 | F29: =C29*SUM($G$23:$G$24) -> 22.5 | G29: 2 | H29: =F29-G29 -> 20.5 | I29: =IFERROR(VLOOKUP($C$24&$B29,'định lượng suất 25k'!$B:$H,7,0),0) -> 90000 | J29: =H29*I29 -> 1845000 | L29: Mắm ruốc | M29: =IFERROR(VLOOKUP($M$24&$L29,'định lượng suất 25k'!$B:$J,9,0),0) -> 0.0064102564 | N29: =IFERROR(VLOOKUP($M$24&$L29,'định lượng suất 25k'!$B:$K,10,0),0) -> 224.35897 | P29: =M29*SUM($Q$23:$Q$24) -> 0.33333333 | R29: =P29-Q29 -> 0.33333333 | S29: =IFERROR(VLOOKUP($M$24&$L29,'định lượng suất 25k'!$B:$H,7,0),0) -> 35000 | T29: =R29*S29 -> 11666.667
B30: Quế | C30: =IFERROR(VLOOKUP($C$24&$B30,'định lượng suất 25k'!$B:$J,9,0),0) -> 0 | D30: =IFERROR(VLOOKUP($C$24&$B30,'định lượng suất 25k'!$B:$K,10,0),0) -> 0 | F30: =C30*SUM($G$23:$G$24) -> 0 | G30: 0.5 | H30: =F30-G30 -> -0.5 | I30: =IFERROR(VLOOKUP($C$24&$B30,'định lượng suất 25k'!$B:$H,7,0),0) -> 0 | J30: =H30*I30 -> 0 | L30: Heo nọng nạc | M30: =IFERROR(VLOOKUP($M$24&$L30,'định lượng suất 25k'!$B:$J,9,0),0) -> 0.015384615 | N30: =IFERROR(VLOOKUP($M$24&$L30,'định lượng suất 25k'!$B:$K,10,0),0) -> 1076.9231 | P30: =M30*SUM($Q$23:$Q$24) -> 0.8 | R30: =P30-Q30 -> 0.8 | S30: =IFERROR(VLOOKUP($M$24&$L30,'định lượng suất 25k'!$B:$H,7,0),0) -> 70000 | T30: =R30*S30 -> 56000
B31: Xà lách | C31: =IFERROR(VLOOKUP($C$24&$B31,'định lượng suất 25k'!$B:$J,9,0),0) -> 0.02 | D31: =IFERROR(VLOOKUP($C$24&$B31,'định lượng suất 25k'!$B:$K,10,0),0) -> 500 | F31: =C31*SUM($G$23:$G$24) -> 6 | G31: 0 | H31: =F31-G31 -> 6 | I31: =IFERROR(VLOOKUP($C$24&$B31,'định lượng suất 25k'!$B:$H,7,0),0) -> 25000 | J31: =H31*I31 -> 150000
B32: Sả | C32: =IFERROR(VLOOKUP($C$24&$B32,'định lượng suất 25k'!$B:$J,9,0),0) -> 0.004 | D32: =IFERROR(VLOOKUP($C$24&$B32,'định lượng suất 25k'!$B:$K,10,0),0) -> 120 | F32: =C32*SUM($G$23:$G$24) -> 1.2 | G32: 0 | H32: =F32-G32 -> 1.2 | I32: =IFERROR(VLOOKUP($C$24&$B32,'định lượng suất 25k'!$B:$H,7,0),0) -> 30000 | J32: =H32*I32 -> 36000
B33: Đậu phộng rang | C33: =IFERROR(VLOOKUP($C$24&$B33,'định lượng suất 25k'!$B:$J,9,0),0) -> 0.006 | D33: =IFERROR(VLOOKUP($C$24&$B33,'định lượng suất 25k'!$B:$K,10,0),0) -> 300 | F33: =C33*SUM($G$23:$G$24) -> 1.8 | G33: 0 | H33: =F33-G33 -> 1.8 | I33: =IFERROR(VLOOKUP($C$24&$B33,'định lượng suất 25k'!$B:$H,7,0),0) -> 50000 | J33: =H33*I33 -> 90000 | L33: Menu | M33: Món Phụ | P33: Suất ăn DAV | Q33: 300
B34: Dưa leo | C34: =IFERROR(VLOOKUP($C$24&$B34,'định lượng suất 25k'!$B:$J,9,0),0) -> 0.02 | D34: =IFERROR(VLOOKUP($C$24&$B34,'định lượng suất 25k'!$B:$K,10,0),0) -> 300 | F34: =C34*SUM($G$23:$G$24) -> 6 | G34: 0 | H34: =F34-G34 -> 6 | I34: =IFERROR(VLOOKUP($C$24&$B34,'định lượng suất 25k'!$B:$H,7,0),0) -> 15000 | J34: =H34*I34 -> 90000 | L34: Món | M34: Đậu khuôn thịt bằm | P34: Suất ăn AVN | Q34: 140
B35: Đu đủ xanh | C35: =IFERROR(VLOOKUP($C$24&$B35,'định lượng suất 25k'!$B:$J,9,0),0) -> 0.02 | D35: =IFERROR(VLOOKUP($C$24&$B35,'định lượng suất 25k'!$B:$K,10,0),0) -> 240 | F35: =C35*SUM($G$23:$G$24) -> 6 | G35: 0 | H35: =F35-G35 -> 6 | I35: =IFERROR(VLOOKUP($C$24&$B35,'định lượng suất 25k'!$B:$H,7,0),0) -> 12000 | J35: =H35*I35 -> 72000 | N35: =SUM(N37:N41) -> 2840.678 | T35: =SUM(T37:T41) -> 193464.41
C36: =IFERROR(VLOOKUP($C$24&$B36,'định lượng suất 25k'!$B:$J,9,0),0) -> 0 | D36: =IFERROR(VLOOKUP($C$24&$B36,'định lượng suất 25k'!$B:$K,10,0),0) -> 0 | F36: =C36*SUM($G$23:$G$24) -> 0 | G36: 0 | H36: =F36-G36 -> 0 | I36: =IFERROR(VLOOKUP($C$24&$B48,'định lượng suất 25k'!$B:$H,7,0),0) -> 0 | J36: =H36*I36 -> 0 | L36: Row Labels | M36: Định lượng (kg) / khay | N36: Cost / khay | P36: Khối lượng yêu cầu (kg) | Q36: Lượng tồn (kg) | R36: Khối lượng cần đặt (kg) | S36: Giá nhập (kg) | T36: Thành tiền
C37: =IFERROR(VLOOKUP($C$24&$B37,'định lượng suất 25k'!$B:$J,9,0),0) -> 0 | D37: =IFERROR(VLOOKUP($C$24&$B37,'định lượng suất 25k'!$B:$K,10,0),0) -> 0 | F37: =C37*SUM($G$23:$G$24) -> 0 | G37: 0 | H37: =F37-G37 -> 0 | I37: =IFERROR(VLOOKUP($C$24&$B49,'định lượng suất 25k'!$B:$H,7,0),0) -> 0 | J37: =H37*I37 -> 0 | L37: Cà rốt | M37: =VLOOKUP($M$34&$L37,'định lượng suất 25k'!$B:$J,9,0) -> 0.016949153 | N37: =VLOOKUP($M$34&$L37,'định lượng suất 25k'!$B:$K,10,0) -> 254.23729 | P37: =M37*SUM($Q$33:$Q$34) -> 7.4576271 | Q37: 0 | R37: =P37-Q37 -> 7.4576271 | S37: =IFERROR(VLOOKUP($M$34&$L37,'định lượng suất 25k'!$B:$H,7,0),0) -> 15000 | T37: =R37*S37 -> 111864.41
C38: =IFERROR(VLOOKUP($C$24&$B38,'định lượng suất 25k'!$B:$J,9,0),0) -> 0 | D38: =IFERROR(VLOOKUP($C$24&$B38,'định lượng suất 25k'!$B:$K,10,0),0) -> 0 | F38: =C38*SUM($G$23:$G$24) -> 0 | G38: 0 | H38: =F38-G38 -> 0 | I38: =IFERROR(VLOOKUP($C$24&$B50,'định lượng suất 25k'!$B:$H,7,0),0) -> 0 | J38: =H38*I38 -> 0 | L38: Đậu khuôn | M38: =VLOOKUP($M$34&$L38,'định lượng suất 25k'!$B:$J,9,0) -> 1 | N38: =VLOOKUP($M$34&$L38,'định lượng suất 25k'!$B:$K,10,0) -> 1600 | P38: =M38*SUM($Q$23:$Q$24) -> 52 | Q38: 1 | R38: =P38-Q38 -> 51 | S38: =IFERROR(VLOOKUP($M$34&$L38,'định lượng suất 25k'!$B:$H,7,0),0) -> 1600 | T38: =R38*S38 -> 81600
C39: =IFERROR(VLOOKUP($C$24&$B39,'định lượng suất 25k'!$B:$J,9,0),0) -> 0 | D39: =IFERROR(VLOOKUP($C$24&$B51,'định lượng suất 25k'!$B:$K,10,0),0) -> 0 | F39: =C39*SUM($G$23:$G$24) -> 0 | G39: 0 | H39: =F39-G39 -> 0 | I39: =IFERROR(VLOOKUP($C$24&$B51,'định lượng suất 25k'!$B:$H,7,0),0) -> 0 | J39: =H39*I39 -> 0 | L39: Nấm mèo | M39: =VLOOKUP($M$34&$L39,'định lượng suất 25k'!$B:$J,9,0) -> 0.0016949153 | N39: =VLOOKUP($M$34&$L39,'định lượng suất 25k'!$B:$K,10,0) -> 186.44068
L40: Thịt bằm | M40: =VLOOKUP($M$34&$L40,'định lượng suất 25k'!$B:$J,9,0) -> 0.01 | N40: =VLOOKUP($M$34&$L40,'định lượng suất 25k'!$B:$K,10,0) -> 800
L43: Menu | M43: Món rau | P43: Suất ăn DAV | Q43: 300
L44: Món | M44: Rau muống xào tỏi | P44: Suất ăn AVN | Q44: 140
N45: =SUM(N47:N49) -> 576 | T45: =SUM(T47:T58) -> 72072
L46: Row Labels | M46: Định lượng (kg) / khay | N46: Cost / khay | P46: Khối lượng yêu cầu (kg) | Q46: Lượng tồn (kg) | R46: Khối lượng cần đặt (kg) | S46: Giá nhập (kg) | T46: Thành tiền
...

Sheet định lượng suất 25k
A2: Supplier | B2: Sub-column | C2: Loại món | D2: Menu | E2: Món | F2: Nguyên liệu chính | G2: Khối lượng ( kg) | H2: Giá nhập (kg) | I2: Số lượng suất ăn | J2: Định lượng (gram) / khay | K2: Cost/khay | L2: Tổng cost 1 suất
A3: NL tươi sống | B3: =E3&F3 -> Bún mọcNạc đùi mông | C3: Món mặn | D3: Món nước | E3: Bún mọc | F3: Nạc đùi mông | G3: 3.5 | H3: 100000 | I3: 100 | J3: =G3/I3 -> 0.035 | K3: =(G3*H3)/I3 -> 3500 | L3: =SUM(K3:K15) -> 13603
A4: NL tươi sống | B4: =E4&F4 -> Bún mọcChả quết | C4: Món mặn | D4: Món nước | E4: Bún mọc | F4: Chả quết | G4: 1.8 | H4: 120000 | I4: 100 | J4: =G4/I4 -> 0.018 | K4: =(G4*H4)/I4 -> 2160
A5: NL tươi sống | B5: =E5&F5 -> Bún mọcThịt xay | C5: Món mặn | D5: Món nước | E5: Bún mọc | F5: Thịt xay | G5: 1 | H5: 80000 | I5: 100 | J5: =G5/I5 -> 0.01 | K5: =(G5*H5)/I5 -> 800
A6: NL tươi sống | B6: =E6&F6 -> Bún mọcChả heo chín | C6: Món mặn | D6: Món nước | E6: Bún mọc | F6: Chả heo chín | G6: 1.3 | H6: 120000 | I6: 100 | J6: =G6/I6 -> 0.013 | K6: =(G6*H6)/I6 -> 1560
A7: NL Rau | B7: =E7&F7 -> Bún mọcNấm mèo | C7: Món mặn | D7: Món nước | E7: Bún mọc | F7: Nấm mèo | G7: 0.3 | H7: 55000 | I7: 100 | J7: =G7/I7 -> 0.003 | K7: =(G7*H7)/I7 -> 165
A8: NL tươi sống | B8: =E8&F8 -> Bún mọcDa heo | C8: Món mặn | D8: Món nước | E8: Bún mọc | F8: Da heo | G8: 2 | H8: 30000 | I8: 100 | J8: =G8/I8 -> 0.02 | K8: =(G8*H8)/I8 -> 600
A9: NL tươi sống | B9: =E9&F9 -> Bún mọcxương ống | C9: Món mặn | D9: Món nước | E9: Bún mọc | F9: xương ống | G9: 1.5 | H9: 30000 | I9: 100 | J9: =G9/I9 -> 0.015 | K9: =(G9*H9)/I9 -> 450
A10: NL Rau | B10: =E10&F10 -> Bún mọcBún | C10: Món mặn | D10: Món nước | E10: Bún mọc | F10: Bún | G10: 33 | H10: 10000 | I10: 100 | J10: =G10/I10 -> 0.33 | K10: =(G10*H10)/I10 -> 3300
A11: NL Rau | B11: =E11&F11 -> Bún mọcRau quế | C11: Món mặn | D11: Món nước | E11: Bún mọc | F11: Rau quế | G11: 0.3 | H11: 30000 | I11: 100 | J11: =G11/I11 -> 0.003 | K11: =(G11*H11)/I11 -> 90
A12: NL Rau | B12: =E12&F12 -> Bún mọcGiá | C12: Món mặn | D12: Món nước | E12: Bún mọc | F12: Giá | G12: 2.5 | H12: 10000 | I12: 100 | J12: =G12/I12 -> 0.025 | K12: =(G12*H12)/I12 -> 250
A13: NL Rau | B13: =E13&F13 -> Bún mọcHành lá | C13: Món mặn | D13: Món nước | E13: Bún mọc | F13: Hành lá | G13: 0.4 | H13: 20000 | I13: 100 | J13: =G13/I13 -> 0.004 | K13: =(G13*H13)/I13 -> 80
A14: NL Rau | B14: =E14&F14 -> Bún mọcChanh | C14: Món mặn | D14: Món nước | E14: Bún mọc | F14: Chanh | G14: 0.8 | H14: 26000 | I14: 100 | J14: =G14/I14 -> 0.008 | K14: =(G14*H14)/I14 -> 208
A15: NL Rau | B15: =E15&F15 -> Bún mọcXà lách | C15: Món mặn | D15: Món nước | E15: Bún mọc | F15: Xà lách | G15: 2 | H15: 22000 | I15: 100 | J15: =G15/I15 -> 0.02 | K15: =(G15*H15)/I15 -> 440
A16: NL tươi sống | B16: =E16&F16 -> Mỳ Quảng Tôm ThịtHeo đùi mông | C16: Món mặn | D16: Món nước | E16: Mỳ Quảng Tôm Thịt | F16: Heo đùi mông | G16: 4.5 | H16: 100000 | I16: 100 | J16: =G16/I16 -> 0.045 | K16: =(G16*H16)/I16 -> 4500 | L16: =SUM(K16:K27) -> 12238
A17: NL tươi sống | B17: =E17&F17 -> Mỳ Quảng Tôm ThịtTrứng cút lột sẵn | C17: Món mặn | D17: Món nước | E17: Mỳ Quảng Tôm Thịt | F17: Trứng cút lột sẵn | G17: 200 | H17: 600 | I17: 100 | J17: =G17/I17 -> 2 | K17: =(G17*H17)/I17 -> 1200
A18: NL tươi sống | B18: =E18&F18 -> Mỳ Quảng Tôm ThịtTôm | C18: Món mặn | D18: Món nước | E18: Mỳ Quảng Tôm Thịt | F18: Tôm | G18: 1.7 | H18: 100000 | I18: 100 | J18: =G18/I18 -> 0.017 | K18: =(G18*H18)/I18 -> 1700
A19: NL Rau | B19: =E19&F19 -> Mỳ Quảng Tôm ThịtBánh phồng tôm | C19: Món mặn | D19: Món nước | E19: Mỳ Quảng Tôm Thịt | F19: Bánh phồng tôm | G19: 3 | H19: 10000 | I19: 100 | J19: =G19/I19 -> 0.03 | K19: =(G19*H19)/I19 -> 300
A20: NL Rau | B20: =E20&F20 -> Mỳ Quảng Tôm ThịtXà lách | C20: Món mặn | D20: Món nước | E20: Mỳ Quảng Tôm Thịt | F20: Xà lách | G20: 2 | H20: 22000 | I20: 100 | J20: =G20/I20 -> 0.02 | K20: =(G20*H20)/I20 -> 440
A21: NL Rau | B21: =E21&F21 -> Mỳ Quảng Tôm ThịtSu trắng | C21: Món mặn | D21: Món nước | E21: Mỳ Quảng Tôm Thịt | F21: Su trắng | G21: 1 | H21: 10000 | I21: 100 | J21: =G21/I21 -> 0.01 | K21: =(G21*H21)/I21 -> 100
A22: NL Rau | B22: =E22&F22 -> Mỳ Quảng Tôm ThịtGiá | C22: Món mặn | D22: Món nước | E22: Mỳ Quảng Tôm Thịt | F22: Giá | G22: 2.5 | H22: 10000 | I22: 100 | J22: =G22/I22 -> 0.025 | K22: =(G22*H22)/I22 -> 250
A23: NL Rau | B23: =E23&F23 -> Mỳ Quảng Tôm ThịtHành lá | C23: Món mặn | D23: Món nước | E23: Mỳ Quảng Tôm Thịt | F23: Hành lá | G23: 0.4 | H23: 20000 | I23: 100 | J23: =G23/I23 -> 0.004 | K23: =(G23*H23)/I23 -> 80
A24: NL Rau | B24: =E24&F24 -> Mỳ Quảng Tôm ThịtNgò gai | C24: Món mặn | D24: Món nước | E24: Mỳ Quảng Tôm Thịt | F24: Ngò gai | G24: 0.2 | H24: 35000 | I24: 100 | J24: =G24/I24 -> 0.002 | K24: =(G24*H24)/I24 -> 70
A25: NL Rau | B25: =E25&F25 -> Mỳ Quảng Tôm ThịtQuế | C25: Món mặn | D25: Món nước | E25: Mỳ Quảng Tôm Thịt | F25: Quế | G25: 0.3 | H25: 30000 | I25: 100 | J25: =G25/I25 -> 0.003 | K25: =(G25*H25)/I25 -> 90
A26: NL Rau | B26: =E26&F26 -> Mỳ Quảng Tôm ThịtChanh | C26: Món mặn | D26: Món nước | E26: Mỳ Quảng Tôm Thịt | F26: Chanh | G26: 0.8 | H26: 26000 | I26: 100 | J26: =G26/I26 -> 0.008 | K26: =(G26*H26)/I26 -> 208
A27: NL Rau | B27: =E27&F27 -> Mỳ Quảng Tôm ThịtMỳ tươi | C27: Món mặn | D27: Món nước | E27: Mỳ Quảng Tôm Thịt | F27: Mỳ tươi | G27: 33 | H27: 10000 | I27: 100 | J27: =G27/I27 -> 0.33 | K27: =(G27*H27)/I27 -> 3300
A28: NL tươi sống | B28: =E28&F28 -> Mỳ Quảng Tôm Thịtcua đồng | C28: Món mặn | D28: Món nước | E28: Mỳ Quảng Tôm Thịt | F28: cua đồng | G28: 0.5 | H28: 50000 | I28: 100 | J28: =G28/I28 -> 0.005 | K28: =(G28*H28)/I28 -> 250
A29: NL tươi sống | B29: =E29&F29 -> Cá kình kho thơmCá kình | C29: Món mặn | D29: Món chính | E29: Cá kình kho thơm | F29: Cá kình | G29: 12 | H29: 40000 | I29: 100 | J29: =G29/I29 -> 0.12 | K29: =(G29*H29)/I29 -> 4800 | L29: =SUM(K29:K36,#REF!) -> #REF! | M29: Suất cơm DAV
A30: NL Rau | B30: =E30&F30 -> Cá kình kho thơmThơm | C30: Món mặn | D30: Món chính | E30: Cá kình kho thơm | F30: Thơm | G30: 7 | H30: 18000 | I30: 300 | J30: =G30/I30 -> 0.023333333 | K30: =(G30*H30)/I30 -> 420
A31: NL tươi sống | B31: =E31&F31 -> Thịt heo luộc giá chuaThịt đùi mông | C31: Món mặn | D31: Món Phụ | E31: Thịt heo luộc giá chua | F31: Thịt đùi mông | G31: 4.5 | H31: 100000 | I31: 100 | J31: =G31/I31 -> 0.045 | K31: =(G31*H31)/I31 -> 4500
A32: NL Rau | B32: =E32&F32 -> Thịt heo luộc giá chuaHành lá | C32: Món mặn | D32: Món Phụ | E32: Thịt heo luộc giá chua | F32: Hành lá | G32: 0.3 | H32: 18000 | I32: 100 | J32: =G32/I32 -> 0.003 | K32: =(G32*H32)/I32 -> 54
A33: NL Rau | B33: =E33&F33 -> Thịt heo luộc giá chuaGiá | C33: Món mặn | D33: Món Phụ | E33: Thịt heo luộc giá chua | F33: Giá | G33: 4 | H33: 10000 | I33: 100 | J33: =G33/I33 -> 0.04 | K33: =(G33*H33)/I33 -> 400
A34: NL Rau | B34: =E34&F34 -> Thịt heo luộc giá chuaCà rốt | C34: Món mặn | D34: Món Phụ | E34: Thịt heo luộc giá chua | F34: Cà rốt | G34: 1 | H34: 15000 | I34: 100 | J34: =G34/I34 -> 0.01 | K34: =(G34*H34)/I34 -> 150
A35: NL Rau | B35: =E35&F35 -> Rau xào thập cẩmRau thập cẩm | C35: Món mặn | D35: Món rau | E35: Rau xào thập cẩm | F35: Rau thập cẩm | G35: 35 | H35: 16000 | I35: 438 | J35: =G35/I35 -> 0.079908676 | K35: =(G35*H35)/I35 -> 1278.5388
A36: NL Rau | B36: =E36&F36 -> Sữa chuaSữa chua | C36: Món mặn | D36: Tráng miệng | E36: Sữa chua | F36: Sữa chua | G36: 290 | H36: 4620 | I36: 290 | J36: =G36/I36 -> 1 | K36: =(G36*H36)/I36 -> 4620
A37: NL tươi sống | B37: =E37&F37 -> Cá nục kho xì dầuCá nục | C37: Món mặn | D37: Món Chính | E37: Cá nục kho xì dầu | F37: Cá nục | G37: 10 | H37: 43000 | I37: 75 | J37: =G37/I37 -> 0.13333333 | K37: =(G37*H37)/I37 -> 5733.3333 | L37: =SUM(K31:K37,#REF!) -> #REF! | M37: Cơm anv
A38: NL tươi sống | B38: =E38&F38 -> Cá chim kho càCá chim | C38: Món mặn | D38: Món chính | E38: Cá chim kho cà | F38: Cá chim | G38: 23 | H38: 37000 | I38: 134 | J38: =G38/I38 -> 0.17164179 | K38: =(G38*H38)/I38 -> 6350.7463 | L38: =SUM(K36,K38:K45) -> 18183.599 | M38: Suất cơm chiều
A39: NL Rau | B39: =E39&F39 -> Cá chim kho càCà chua | C39: Món mặn | D39: Món chính | E39: Cá chim kho cà | F39: Cà chua | G39: 3 | H39: 20000 | I39: 134 | J39: =G39/I39 -> 0.02238806 | K39: =(G39*H39)/I39 -> 447.76119
A40: NL tươi sống | B40: =E40&F40 -> Tôm thịt rimTôm | C40: Món mặn | D40: Món chính | E40: Tôm thịt rim | F40: Tôm | G40: 2.5 | H40: 115000 | I40: 134 | J40: =G40/I40 -> 0.018656716 | K40: =(G40*H40)/I40 -> 2145.5224
A41: NL tươi sống | B41: =E41&F41 -> Tôm thịt rimThịt nọng | C41: Món mặn | D41: Món chính | E41: Tôm thịt rim | F41: Thịt nọng | G41: 1.5 | H41: 60000 | I41: 134 | J41: =G41/I41 -> 0.01119403 | K41: =(G41*H41)/I41 -> 671.64179
...

Sheet định lượng suất 30k
A2: Supplier | B2: Sub-column | C2: Loại món | D2: Menu | E2: Món | F2: Nguyên liệu chính | G2: Khối lượng ( kg) | H2: Giá nhập (kg) | I2: Số lượng suất ăn | J2: Định lượng (gram) / khay | K2: Cost/khay | L2: Tổng cost 1 suất
A3: NL tươi sống | B3: =E3&F3 -> Bún mọcNạc đùi mông | C3: Món mặn | D3: Món nước | E3: Bún mọc | F3: Nạc đùi mông | G3: 4.2 | H3: 100000 | I3: 100 | J3: =G3/I3 -> 0.042 | K3: =(G3*H3)/I3 -> 4200 | L3: =SUM(K3:K15) -> 14943
A4: NL tươi sống | B4: =E4&F4 -> Bún mọcChả quết | C4: Món mặn | D4: Món nước | E4: Bún mọc | F4: Chả quết | G4: 2.2 | H4: 120000 | I4: 100 | J4: =G4/I4 -> 0.022 | K4: =(G4*H4)/I4 -> 2640
A5: NL tươi sống | B5: =E5&F5 -> Bún mọcThịt xay | C5: Món mặn | D5: Món nước | E5: Bún mọc | F5: Thịt xay | G5: 1.2 | H5: 80000 | I5: 100 | J5: =G5/I5 -> 0.012 | K5: =(G5*H5)/I5 -> 960
A6: NL tươi sống | B6: =E6&F6 -> Bún mọcChả heo chín | C6: Món mặn | D6: Món nước | E6: Bún mọc | F6: Chả heo chín | G6: 1.3 | H6: 120000 | I6: 100 | J6: =G6/I6 -> 0.013 | K6: =(G6*H6)/I6 -> 1560
A7: NL Rau | B7: =E7&F7 -> Bún mọcNấm mèo | C7: Món mặn | D7: Món nước | E7: Bún mọc | F7: Nấm mèo | G7: 0.3 | H7: 55000 | I7: 100 | J7: =G7/I7 -> 0.003 | K7: =(G7*H7)/I7 -> 165
A8: NL tươi sống | B8: =E8&F8 -> Bún mọcDa heo | C8: Món mặn | D8: Món nước | E8: Bún mọc | F8: Da heo | G8: 2 | H8: 30000 | I8: 100 | J8: =G8/I8 -> 0.02 | K8: =(G8*H8)/I8 -> 600
A9: NL tươi sống | B9: =E9&F9 -> Bún mọcxương ống | C9: Món mặn | D9: Món nước | E9: Bún mọc | F9: xương ống | G9: 1.5 | H9: 30000 | I9: 100 | J9: =G9/I9 -> 0.015 | K9: =(G9*H9)/I9 -> 450
A10: NL Rau | B10: =E10&F10 -> Bún mọcBún | C10: Món mặn | D10: Món nước | E10: Bún mọc | F10: Bún | G10: 33 | H10: 10000 | I10: 100 | J10: =G10/I10 -> 0.33 | K10: =(G10*H10)/I10 -> 3300
A11: NL Rau | B11: =E11&F11 -> Bún mọcRau quế | C11: Món mặn | D11: Món nước | E11: Bún mọc | F11: Rau quế | G11: 0.3 | H11: 30000 | I11: 100 | J11: =G11/I11 -> 0.003 | K11: =(G11*H11)/I11 -> 90
A12: NL Rau | B12: =E12&F12 -> Bún mọcGiá | C12: Món mặn | D12: Món nước | E12: Bún mọc | F12: Giá | G12: 2.5 | H12: 10000 | I12: 100 | J12: =G12/I12 -> 0.025 | K12: =(G12*H12)/I12 -> 250
A13: NL Rau | B13: =E13&F13 -> Bún mọcHành lá | C13: Món mặn | D13: Món nước | E13: Bún mọc | F13: Hành lá | G13: 0.4 | H13: 20000 | I13: 100 | J13: =G13/I13 -> 0.004 | K13: =(G13*H13)/I13 -> 80
A14: NL Rau | B14: =E14&F14 -> Bún mọcChanh | C14: Món mặn | D14: Món nước | E14: Bún mọc | F14: Chanh | G14: 0.8 | H14: 26000 | I14: 100 | J14: =G14/I14 -> 0.008 | K14: =(G14*H14)/I14 -> 208
A15: NL Rau | B15: =E15&F15 -> Bún mọcXà lách | C15: Món mặn | D15: Món nước | E15: Bún mọc | F15: Xà lách | G15: 2 | H15: 22000 | I15: 100 | J15: =G15/I15 -> 0.02 | K15: =(G15*H15)/I15 -> 440
A16: NL tươi sống | B16: =E16&F16 -> Mỳ Quảng Tôm ThịtHeo đùi mông | C16: Món mặn | D16: Món nước | E16: Mỳ Quảng Tôm Thịt | F16: Heo đùi mông | G16: 5.5 | H16: 100000 | I16: 100 | J16: =G16/I16 -> 0.055 | K16: =(G16*H16)/I16 -> 5500 | L16: =SUM(K16:K27) -> 14638
A17: NL tươi sống | B17: =E17&F17 -> Mỳ Quảng Tôm ThịtTrứng cút lột sẵn | C17: Món mặn | D17: Món nước | E17: Mỳ Quảng Tôm Thịt | F17: Trứng cút lột sẵn | G17: 300 | H17: 600 | I17: 100 | J17: =G17/I17 -> 3 | K17: =(G17*H17)/I17 -> 1800
A18: NL tươi sống | B18: =E18&F18 -> Mỳ Quảng Tôm ThịtTôm | C18: Món mặn | D18: Món nước | E18: Mỳ Quảng Tôm Thịt | F18: Tôm | G18: 2.5 | H18: 100000 | I18: 100 | J18: =G18/I18 -> 0.025 | K18: =(G18*H18)/I18 -> 2500
A19: NL Rau | B19: =E19&F19 -> Mỳ Quảng Tôm ThịtBánh phồng tôm | C19: Món mặn | D19: Món nước | E19: Mỳ Quảng Tôm Thịt | F19: Bánh phồng tôm | G19: 3 | H19: 10000 | I19: 100 | J19: =G19/I19 -> 0.03 | K19: =(G19*H19)/I19 -> 300
A20: NL Rau | B20: =E20&F20 -> Mỳ Quảng Tôm ThịtXà lách | C20: Món mặn | D20: Món nước | E20: Mỳ Quảng Tôm Thịt | F20: Xà lách | G20: 2 | H20: 22000 | I20: 100 | J20: =G20/I20 -> 0.02 | K20: =(G20*H20)/I20 -> 440
A21: NL Rau | B21: =E21&F21 -> Mỳ Quảng Tôm ThịtSu trắng | C21: Món mặn | D21: Món nước | E21: Mỳ Quảng Tôm Thịt | F21: Su trắng | G21: 1 | H21: 10000 | I21: 100 | J21: =G21/I21 -> 0.01 | K21: =(G21*H21)/I21 -> 100
A22: NL Rau | B22: =E22&F22 -> Mỳ Quảng Tôm ThịtGiá | C22: Món mặn | D22: Món nước | E22: Mỳ Quảng Tôm Thịt | F22: Giá | G22: 2.5 | H22: 10000 | I22: 100 | J22: =G22/I22 -> 0.025 | K22: =(G22*H22)/I22 -> 250
A23: NL Rau | B23: =E23&F23 -> Mỳ Quảng Tôm ThịtHành lá | C23: Món mặn | D23: Món nước | E23: Mỳ Quảng Tôm Thịt | F23: Hành lá | G23: 0.4 | H23: 20000 | I23: 100 | J23: =G23/I23 -> 0.004 | K23: =(G23*H23)/I23 -> 80
A24: NL Rau | B24: =E24&F24 -> Mỳ Quảng Tôm ThịtNgò gai | C24: Món mặn | D24: Món nước | E24: Mỳ Quảng Tôm Thịt | F24: Ngò gai | G24: 0.2 | H24: 35000 | I24: 100 | J24: =G24/I24 -> 0.002 | K24: =(G24*H24)/I24 -> 70
A25: NL Rau | B25: =E25&F25 -> Mỳ Quảng Tôm ThịtQuế | C25: Món mặn | D25: Món nước | E25: Mỳ Quảng Tôm Thịt | F25: Quế | G25: 0.3 | H25: 30000 | I25: 100 | J25: =G25/I25 -> 0.003 | K25: =(G25*H25)/I25 -> 90
A26: NL Rau | B26: =E26&F26 -> Mỳ Quảng Tôm ThịtChanh | C26: Món mặn | D26: Món nước | E26: Mỳ Quảng Tôm Thịt | F26: Chanh | G26: 0.8 | H26: 26000 | I26: 100 | J26: =G26/I26 -> 0.008 | K26: =(G26*H26)/I26 -> 208
A27: NL Rau | B27: =E27&F27 -> Mỳ Quảng Tôm ThịtMỳ tươi | C27: Món mặn | D27: Món nước | E27: Mỳ Quảng Tôm Thịt | F27: Mỳ tươi | G27: 33 | H27: 10000 | I27: 100 | J27: =G27/I27 -> 0.33 | K27: =(G27*H27)/I27 -> 3300
A28: NL tươi sống | B28: =E28&F28 -> Mỳ Quảng Tôm Thịtcua đồng | C28: Món mặn | D28: Món nước | E28: Mỳ Quảng Tôm Thịt | F28: cua đồng | G28: 0.5 | H28: 50000 | I28: 100 | J28: =G28/I28 -> 0.005 | K28: =(G28*H28)/I28 -> 250
A29: NL tươi sống | B29: =E29&F29 -> Cá kình kho thơmCá kình | C29: Món mặn | D29: Món chính | E29: Cá kình kho thơm | F29: Cá kình | G29: 12 | H29: 40000 | I29: 100 | J29: =G29/I29 -> 0.12 | K29: =(G29*H29)/I29 -> 4800 | L29: =SUM(K29:K36,#REF!) -> #REF! | M29: Suất cơm DAV
A30: NL Rau | B30: =E30&F30 -> Cá kình kho thơmThơm | C30: Món mặn | D30: Món chính | E30: Cá kình kho thơm | F30: Thơm | G30: 7 | H30: 18000 | I30: 300 | J30: =G30/I30 -> 0.023333333 | K30: =(G30*H30)/I30 -> 420 | O30: =G30*1.1 -> 7.7
A31: NL tươi sống | B31: =E31&F31 -> Thịt heo luộc giá chuaThịt đùi mông | C31: Món mặn | D31: Món Phụ | E31: Thịt heo luộc giá chua | F31: Thịt đùi mông | G31: 4.5 | H31: 100000 | I31: 100 | J31: =G31/I31 -> 0.045 | K31: =(G31*H31)/I31 -> 4500
A32: NL Rau | B32: =E32&F32 -> Thịt heo luộc giá chuaHành lá | C32: Món mặn | D32: Món Phụ | E32: Thịt heo luộc giá chua | F32: Hành lá | G32: 0.3 | H32: 18000 | I32: 100 | J32: =G32/I32 -> 0.003 | K32: =(G32*H32)/I32 -> 54
A33: NL Rau | B33: =E33&F33 -> Thịt heo luộc giá chuaGiá | C33: Món mặn | D33: Món Phụ | E33: Thịt heo luộc giá chua | F33: Giá | G33: 4 | H33: 10000 | I33: 100 | J33: =G33/I33 -> 0.04 | K33: =(G33*H33)/I33 -> 400
A34: NL Rau | B34: =E34&F34 -> Thịt heo luộc giá chuaCà rốt | C34: Món mặn | D34: Món Phụ | E34: Thịt heo luộc giá chua | F34: Cà rốt | G34: 1 | H34: 15000 | I34: 100 | J34: =G34/I34 -> 0.01 | K34: =(G34*H34)/I34 -> 150
A35: NL Rau | B35: =E35&F35 -> Rau xào thập cẩmRau thập cẩm | C35: Món mặn | D35: Món rau | E35: Rau xào thập cẩm | F35: Rau thập cẩm | G35: 35 | H35: 16000 | I35: 438 | J35: =G35/I35 -> 0.079908676 | K35: =(G35*H35)/I35 -> 1278.5388
A36: NL Rau | B36: =E36&F36 -> Sữa chuaSữa chua | C36: Món mặn | D36: Tráng miệng | E36: Sữa chua | F36: Sữa chua | G36: 290 | H36: 4620 | I36: 290 | J36: =G36/I36 -> 1 | K36: =(G36*H36)/I36 -> 4620
A37: NL tươi sống | B37: =E37&F37 -> Cá nục kho xì dầuCá nục | C37: Món mặn | D37: Món Chính | E37: Cá nục kho xì dầu | F37: Cá nục | G37: 10 | H37: 43000 | I37: 75 | J37: =G37/I37 -> 0.13333333 | K37: =(G37*H37)/I37 -> 5733.3333 | L37: =SUM(K31:K37,#REF!) -> #REF! | M37: Cơm anv
A38: NL tươi sống | B38: =E38&F38 -> Cá chim kho càCá chim | C38: Món mặn | D38: Món chính | E38: Cá chim kho cà | F38: Cá chim | G38: 23 | H38: 37000 | I38: 134 | J38: =G38/I38 -> 0.17164179 | K38: =(G38*H38)/I38 -> 6350.7463 | L38: =SUM(K36,K38:K45) -> 18183.599 | M38: Suất cơm chiều
A39: NL Rau | B39: =E39&F39 -> Cá chim kho càCà chua | C39: Món mặn | D39: Món chính | E39: Cá chim kho cà | F39: Cà chua | G39: 3 | H39: 20000 | I39: 134 | J39: =G39/I39 -> 0.02238806 | K39: =(G39*H39)/I39 -> 447.76119 | O39: =G39*1.1 -> 3.3
A40: NL tươi sống | B40: =E40&F40 -> Tôm thịt rimTôm | C40: Món mặn | D40: Món chính | E40: Tôm thịt rim | F40: Tôm | G40: 2.5 | H40: 115000 | I40: 134 | J40: =G40/I40 -> 0.018656716 | K40: =(G40*H40)/I40 -> 2145.5224
A41: NL tươi sống | B41: =E41&F41 -> Tôm thịt rimThịt nọng | C41: Món mặn | D41: Món chính | E41: Tôm thịt rim | F41: Thịt nọng | G41: 1.5 | H41: 60000 | I41: 134 | J41: =G41/I41 -> 0.01119403 | K41: =(G41*H41)/I41 -> 671.64179
...

Sheet định lượng suất 34k
A2: Supplier | B2: Sub-column | C2: Loại món | D2: Menu | E2: Món | F2: Nguyên liệu chính | G2: Khối lượng ( kg) | H2: Giá nhập (kg) | I2: Số lượng suất ăn | J2: Định lượng (gram) / khay | K2: Cost/khay | L2: Tổng cost 1 suất
A3: NL tươi sống | B3: =E3&F3 -> Bún mọcNạc đùi mông | C3: Món mặn | D3: Món nước | E3: Bún mọc | F3: Nạc đùi mông | G3: 5 | H3: 100000 | I3: 100 | J3: =G3/I3 -> 0.05 | K3: =(G3*H3)/I3 -> 5000 | L3: =SUM(K3:K15) -> 17843
A4: NL tươi sống | B4: =E4&F4 -> Bún mọcChả quết | C4: Món mặn | D4: Món nước | E4: Bún mọc | F4: Chả quết | G4: 2.5 | H4: 120000 | I4: 100 | J4: =G4/I4 -> 0.025 | K4: =(G4*H4)/I4 -> 3000
A5: NL tươi sống | B5: =E5&F5 -> Bún mọcThịt xay | C5: Món mặn | D5: Món nước | E5: Bún mọc | F5: Thịt xay | G5: 1.2 | H5: 80000 | I5: 100 | J5: =G5/I5 -> 0.012 | K5: =(G5*H5)/I5 -> 960
A6: NL tươi sống | B6: =E6&F6 -> Bún mọcChả heo chín | C6: Món mặn | D6: Món nước | E6: Bún mọc | F6: Chả heo chín | G6: 2.5 | H6: 120000 | I6: 100 | J6: =G6/I6 -> 0.025 | K6: =(G6*H6)/I6 -> 3000
A7: NL Rau | B7: =E7&F7 -> Bún mọcNấm mèo | C7: Món mặn | D7: Món nước | E7: Bún mọc | F7: Nấm mèo | G7: 0.3 | H7: 55000 | I7: 100 | J7: =G7/I7 -> 0.003 | K7: =(G7*H7)/I7 -> 165
A8: NL tươi sống | B8: =E8&F8 -> Bún mọcDa heo | C8: Món mặn | D8: Món nước | E8: Bún mọc | F8: Da heo | G8: 3 | H8: 30000 | I8: 100 | J8: =G8/I8 -> 0.03 | K8: =(G8*H8)/I8 -> 900
A9: NL tươi sống | B9: =E9&F9 -> Bún mọcxương ống | C9: Món mặn | D9: Món nước | E9: Bún mọc | F9: xương ống | G9: 1.5 | H9: 30000 | I9: 100 | J9: =G9/I9 -> 0.015 | K9: =(G9*H9)/I9 -> 450
A10: NL Rau | B10: =E10&F10 -> Bún mọcBún | C10: Món mặn | D10: Món nước | E10: Bún mọc | F10: Bún | G10: 33 | H10: 10000 | I10: 100 | J10: =G10/I10 -> 0.33 | K10: =(G10*H10)/I10 -> 3300
A11: NL Rau | B11: =E11&F11 -> Bún mọcRau quế | C11: Món mặn | D11: Món nước | E11: Bún mọc | F11: Rau quế | G11: 0.3 | H11: 30000 | I11: 100 | J11: =G11/I11 -> 0.003 | K11: =(G11*H11)/I11 -> 90
A12: NL Rau | B12: =E12&F12 -> Bún mọcGiá | C12: Món mặn | D12: Món nước | E12: Bún mọc | F12: Giá | G12: 2.5 | H12: 10000 | I12: 100 | J12: =G12/I12 -> 0.025 | K12: =(G12*H12)/I12 -> 250
A13: NL Rau | B13: =E13&F13 -> Bún mọcHành lá | C13: Món mặn | D13: Món nước | E13: Bún mọc | F13: Hành lá | G13: 0.4 | H13: 20000 | I13: 100 | J13: =G13/I13 -> 0.004 | K13: =(G13*H13)/I13 -> 80
A14: NL Rau | B14: =E14&F14 -> Bún mọcChanh | C14: Món mặn | D14: Món nước | E14: Bún mọc | F14: Chanh | G14: 0.8 | H14: 26000 | I14: 100 | J14: =G14/I14 -> 0.008 | K14: =(G14*H14)/I14 -> 208
A15: NL Rau | B15: =E15&F15 -> Bún mọcXà lách | C15: Món mặn | D15: Món nước | E15: Bún mọc | F15: Xà lách | G15: 2 | H15: 22000 | I15: 100 | J15: =G15/I15 -> 0.02 | K15: =(G15*H15)/I15 -> 440
A16: NL tươi sống | B16: =E16&F16 -> Mỳ Quảng Tôm ThịtHeo đùi mông | C16: Món mặn | D16: Món nước | E16: Mỳ Quảng Tôm Thịt | F16: Heo đùi mông | G16: 4.5 | H16: 100000 | I16: 100 | J16: =G16/I16 -> 0.045 | K16: =(G16*H16)/I16 -> 4500 | L16: =SUM(K16:K28) -> 18138
A17: NL tươi sống | B17: =E17&F17 -> Mỳ Quảng Tôm ThịtTrứng cút lột sẵn | C17: Món mặn | D17: Món nước | E17: Mỳ Quảng Tôm Thịt | F17: Trứng cút lột sẵn | G17: 300 | H17: 600 | I17: 100 | J17: =G17/I17 -> 3 | K17: =(G17*H17)/I17 -> 1800
A18: NL tươi sống | B18: =E18&F18 -> Mỳ Quảng Tôm ThịtTôm | C18: Món mặn | D18: Món nước | E18: Mỳ Quảng Tôm Thịt | F18: Tôm | G18: 2.5 | H18: 100000 | I18: 100 | J18: =G18/I18 -> 0.025 | K18: =(G18*H18)/I18 -> 2500
A19: NL tươi sống | B19: =E19&F19 -> Mỳ Quảng Tôm Thịtchả heo chiên | C19: Món mặn | D19: Món nước | E19: Mỳ Quảng Tôm Thịt | F19: chả heo chiên | G19: 3 | H19: 140000 | I19: 100 | J19: =G19/I19 -> 0.03 | K19: =(G19*H19)/I19 -> 4200
A20: NL Rau | B20: =E20&F20 -> Mỳ Quảng Tôm ThịtBánh phồng tôm | C20: Món mặn | D20: Món nước | E20: Mỳ Quảng Tôm Thịt | F20: Bánh phồng tôm | G20: 6 | H20: 10000 | I20: 100 | J20: =G20/I20 -> 0.06 | K20: =(G20*H20)/I20 -> 600
A21: NL Rau | B21: =E21&F21 -> Mỳ Quảng Tôm ThịtXà lách | C21: Món mặn | D21: Món nước | E21: Mỳ Quảng Tôm Thịt | F21: Xà lách | G21: 2 | H21: 22000 | I21: 100 | J21: =G21/I21 -> 0.02 | K21: =(G21*H21)/I21 -> 440
A22: NL Rau | B22: =E22&F22 -> Mỳ Quảng Tôm ThịtSu trắng | C22: Món mặn | D22: Món nước | E22: Mỳ Quảng Tôm Thịt | F22: Su trắng | G22: 1 | H22: 10000 | I22: 100 | J22: =G22/I22 -> 0.01 | K22: =(G22*H22)/I22 -> 100
A23: NL Rau | B23: =E23&F23 -> Mỳ Quảng Tôm ThịtGiá | C23: Món mặn | D23: Món nước | E23: Mỳ Quảng Tôm Thịt | F23: Giá | G23: 2.5 | H23: 10000 | I23: 100 | J23: =G23/I23 -> 0.025 | K23: =(G23*H23)/I23 -> 250
A24: NL Rau | B24: =E24&F24 -> Mỳ Quảng Tôm ThịtHành lá | C24: Món mặn | D24: Món nước | E24: Mỳ Quảng Tôm Thịt | F24: Hành lá | G24: 0.4 | H24: 20000 | I24: 100 | J24: =G24/I24 -> 0.004 | K24: =(G24*H24)/I24 -> 80
A25: NL Rau | B25: =E25&F25 -> Mỳ Quảng Tôm ThịtNgò gai | C25: Món mặn | D25: Món nước | E25: Mỳ Quảng Tôm Thịt | F25: Ngò gai | G25: 0.2 | H25: 35000 | I25: 100 | J25: =G25/I25 -> 0.002 | K25: =(G25*H25)/I25 -> 70
A26: NL Rau | B26: =E26&F26 -> Mỳ Quảng Tôm ThịtQuế | C26: Món mặn | D26: Món nước | E26: Mỳ Quảng Tôm Thịt | F26: Quế | G26: 0.3 | H26: 30000 | I26: 100 | J26: =G26/I26 -> 0.003 | K26: =(G26*H26)/I26 -> 90
A27: NL Rau | B27: =E27&F27 -> Mỳ Quảng Tôm ThịtChanh | C27: Món mặn | D27: Món nước | E27: Mỳ Quảng Tôm Thịt | F27: Chanh | G27: 0.8 | H27: 26000 | I27: 100 | J27: =G27/I27 -> 0.008 | K27: =(G27*H27)/I27 -> 208
A28: NL Rau | B28: =E28&F28 -> Mỳ Quảng Tôm ThịtMỳ tươi | C28: Món mặn | D28: Món nước | E28: Mỳ Quảng Tôm Thịt | F28: Mỳ tươi | G28: 33 | H28: 10000 | I28: 100 | J28: =G28/I28 -> 0.33 | K28: =(G28*H28)/I28 -> 3300
A29: NL tươi sống | B29: =E29&F29 -> Mỳ Quảng Tôm Thịtcua đồng | C29: Món mặn | D29: Món nước | E29: Mỳ Quảng Tôm Thịt | F29: cua đồng | G29: 0.5 | H29: 50000 | I29: 100 | J29: =G29/I29 -> 0.005 | K29: =(G29*H29)/I29 -> 250
A30: NL tươi sống | B30: =E30&F30 -> Cá kình kho thơmCá kình | C30: Món mặn | D30: Món chính | E30: Cá kình kho thơm | F30: Cá kình | G30: 12 | H30: 40000 | I30: 100 | J30: =G30/I30 -> 0.12 | K30: =(G30*H30)/I30 -> 4800 | L30: =SUM(K30:K37,#REF!) -> #REF! | M30: Suất cơm DAV
A31: NL Rau | B31: =E31&F31 -> Cá kình kho thơmThơm | C31: Món mặn | D31: Món chính | E31: Cá kình kho thơm | F31: Thơm | G31: 7 | H31: 18000 | I31: 300 | J31: =G31/I31 -> 0.023333333 | K31: =(G31*H31)/I31 -> 420
A32: NL tươi sống | B32: =E32&F32 -> Thịt heo luộc giá chuaThịt đùi mông | C32: Món mặn | D32: Món Phụ | E32: Thịt heo luộc giá chua | F32: Thịt đùi mông | G32: 4.5 | H32: 100000 | I32: 100 | J32: =G32/I32 -> 0.045 | K32: =(G32*H32)/I32 -> 4500
A33: NL Rau | B33: =E33&F33 -> Thịt heo luộc giá chuaHành lá | C33: Món mặn | D33: Món Phụ | E33: Thịt heo luộc giá chua | F33: Hành lá | G33: 0.3 | H33: 18000 | I33: 100 | J33: =G33/I33 -> 0.003 | K33: =(G33*H33)/I33 -> 54
A34: NL Rau | B34: =E34&F34 -> Thịt heo luộc giá chuaGiá | C34: Món mặn | D34: Món Phụ | E34: Thịt heo luộc giá chua | F34: Giá | G34: 4 | H34: 10000 | I34: 100 | J34: =G34/I34 -> 0.04 | K34: =(G34*H34)/I34 -> 400
A35: NL Rau | B35: =E35&F35 -> Thịt heo luộc giá chuaCà rốt | C35: Món mặn | D35: Món Phụ | E35: Thịt heo luộc giá chua | F35: Cà rốt | G35: 1 | H35: 15000 | I35: 100 | J35: =G35/I35 -> 0.01 | K35: =(G35*H35)/I35 -> 150
A36: NL Rau | B36: =E36&F36 -> Rau xào thập cẩmRau thập cẩm | C36: Món mặn | D36: Món rau | E36: Rau xào thập cẩm | F36: Rau thập cẩm | G36: 35 | H36: 16000 | I36: 438 | J36: =G36/I36 -> 0.079908676 | K36: =(G36*H36)/I36 -> 1278.5388
A37: NL Rau | B37: =E37&F37 -> Sữa chuaSữa chua | C37: Món mặn | D37: Tráng miệng | E37: Sữa chua | F37: Sữa chua | G37: 290 | H37: 4620 | I37: 290 | J37: =G37/I37 -> 1 | K37: =(G37*H37)/I37 -> 4620
A38: NL tươi sống | B38: =E38&F38 -> Cá nục kho xì dầuCá nục | C38: Món mặn | D38: Món Chính | E38: Cá nục kho xì dầu | F38: Cá nục | G38: 10 | H38: 43000 | I38: 75 | J38: =G38/I38 -> 0.13333333 | K38: =(G38*H38)/I38 -> 5733.3333 | L38: =SUM(K32:K38,#REF!) -> #REF! | M38: Cơm anv
A39: NL tươi sống | B39: =E39&F39 -> Cá chim kho càCá chim | C39: Món mặn | D39: Món chính | E39: Cá chim kho cà | F39: Cá chim | G39: 23 | H39: 37000 | I39: 134 | J39: =G39/I39 -> 0.17164179 | K39: =(G39*H39)/I39 -> 6350.7463 | L39: =SUM(K37,K39:K46) -> 18183.599 | M39: Suất cơm chiều
A40: NL Rau | B40: =E40&F40 -> Cá chim kho càCà chua | C40: Món mặn | D40: Món chính | E40: Cá chim kho cà | F40: Cà chua | G40: 3 | H40: 20000 | I40: 134 | J40: =G40/I40 -> 0.02238806 | K40: =(G40*H40)/I40 -> 447.76119
A41: NL tươi sống | B41: =E41&F41 -> Tôm thịt rimTôm | C41: Món mặn | D41: Món chính | E41: Tôm thịt rim | F41: Tôm | G41: 2.5 | H41: 115000 | I41: 134 | J41: =G41/I41 -> 0.018656716 | K41: =(G41*H41)/I41 -> 2145.5224
...

Sheet menu
B2: Menu suất ăn 25k
B4: MENU MẶN
B5: Món mặn 1 | C5: THỊT KHO SẢ RUỐC | D5: CỐT LẾT NƯỚNG | E5: CÁ NỤC CHIÊN MẮM TỎI | F5: THỊT KHO CỦ CẢI | G5: GÀ CHIÊN MẮM | H5: THỊT LUỘC GIÁ CHUA
B6: Món mặn 2 | C6: TÔM XÀO MƯỚP | D6: TRỨNG ỐP LA | E6: HEO XÀO CẢI CHUA | F6: CHẢ CÁ SỐT CÀ | G6: TRỨNG CHIÊN THẬP CẨM | H6: CÁ NGỪ KHO DƯA
B7: Rau | C7: CÀ TÍM MỠ HÀNH | D7: RAU LANG LUỘC | E7: GIÁ XÀO HẸ | F7: CẢI THÌA LUỘC | G7: SU TRẮNG LUỘC | H7: CẢI NGỌT LUỘC
B8: Canh | C8: CANH CHUA | D8: KHỔ QUA NẤU TÔM | E8: BẦU NẤU TÔM | F8: MỒNG TƠI NẤU TÔM | G8: BÍ ĐAO NẤU TÔM | H8: RAU MÁ THỊT XAY
B9: Trái cây | C9: TRÁI CÂY | D9: TRÁI CÂY | E9: TRÁI CÂY | F9: TRÁI CÂY | G9: TRÁI CÂY | H9: TRÁI CÂY
B11: MENU MẶN
B12: Món mặn 1 | C12: THỊT KHO ĐẬU KHUÔN | D12: VỊT NẤU LAGU | E12: THỊT XÀO CỦ QUẢ | F12: CÁ PHÈN KHO RIM | G12: GIÒ HEO UM ĐẬU | H12: HEO XÀO ĐẬU ĐŨA
B13: Món mặn 2 | C13: CÁ ĐÙ CHIÊN MẮM | D13: TRỨNG LUỘC | E13: TÔM RIM CHẢ | F13: THỊT RIM TRỨNG CÚT | G13: TRỨNG CHIÊN THẬP CẨM | H13: CÁ MỐI RIM NGHỆ
B14: Rau | C14: SU TRẮNG LUỘC | D14: CÀ TÍM MỠ HÀNH | E14: BẦU HẤP | F14: GIÁ XÀO HẸ | G14: RAU MUỐNG XÀO | H14: CẢI NGỌT LUỘC
B15: Canh | C15: CANH CHUA | D15: BỒ NGÓT NẤU TÔM | E15: KHỔ QUA THỊT XAY | F15: MỒNG TƠI NẤU TÔM | G15: BÍ ĐỎ NẤU TÔM | H15: RAU MÁ THỊT XAY
B16: Trái cây | C16: TRÁI CÂY | D16: TRÁI CÂY | E16: TRÁI CÂY | F16: TRÁI CÂY | G16: TRÁI CÂY | H16: TRÁI CÂY
B18: MENU MẶN
B19: Món mặn 1 | C19: MỲ GÀ | D19: GÀ XÉ TRỘN HÀNH | E19: CÁ NGỪ SỐT MẮM | F19: BÚN RIÊU CUA | G19: THỊT HEO RIM TÔM | H19: THỊT XÀO CẢI CHUA
B20: Món mặn 2 | D20: TRỨNG ỐP LA | E20: THỊT LUỘC MẮM NÊM | G20: CHẢ CÁ NHỒNG SỐT CÀ | H20: CÁ PHÈN CHIÊN
B21: Rau | D21: SU TRẮNG LUỘC | E21: RAU LANG LUỘC | G21: CÀ TÍM MỠ HÀNH | H21: SU SU XÀO
B22: Canh | D22: BẦU NẤU THỊT BẰM | E22: MỒNG TƠI NẤU TÔM | G22: BÍ ĐAO NẤU TÔM | H22: RAU MÁ THỊT XAY
B23: Trái cây | C23: TRÁI CÂY | D23: TRÁI CÂY | E23: TRÁI CÂY | F23: TRÁI CÂY | G23: TRÁI CÂY | H23: TRÁI CÂY
B26: MENU MẶN
B27: Món mặn 1 | C27: MỲ CÁ LÓC | D27: GÀ KHO SẢ | E27: CÁ HỐ CHIÊN | F27: BÚN XƯƠNG | G27: THỊT KHO SẢ RUỐC | H27: CÁ NỤC KHO KEO
B28: Món mặn 2 | D28: ĐẬU KHUÔN NHỒI THỊT | E28: BÚN TRỘN TÔM THỊT | G28: TÔM XÀO CỦ QUẢ | H28: THỊT HEO XÁ XÍU
B29: Rau | D29: CỦ QUẢ LUỘC | E29: GIÁ XÀO HẸ | G29: CÀ TÍM MỠ HÀNH | H29: RAU MUỐNG XÀO
B30: Canh | D30: BẦU NẤU THỊT BẰM | E30: MỒNG TƠI NẤU TÔM | G30: BÍ ĐAO NẤU TÔM | H30: RAU MÁ THỊT XAY
B31: Trái cây | C31: TRÁI CÂY | D31: TRÁI CÂY | E31: TRÁI CÂY | F31: TRÁI CÂY | G31: TRÁI CÂY | H31: TRÁI CÂY
B33: Menu suất ăn 30k
B35: MENU MẶN
B36: Món mặn 1 | C36: BÚN CÁ NGỪ | D36: THỊT RIM TRỨNG CÚT | E36: THỊT XÀO ĐẬU ĐŨA | F36: CÀ RI GÀ + BÁNH MÌ | G36: GÀ CHIÊN MẮM | H36: CÁ NỤC KHO KEO
B37: Món mặn 2 | D37: TÔM RANG MUỐI SẢ | E37: CÁ CHUỒN KHO MÍT | G37: TRỨNG LUỘC | H37: HEO XÀO CẢI CHUA
B38: Rau | D38: CÀ TÍM MỠ HÀNH | E38: CẢI NGỌT LUỘC | G38: SU TRẮNG LUỘC | H38: RAU LANG LUỘC
B39: Canh | D39: BÍ ĐAO NẤU TÔM | E39: RAU MÁ THỊT XAY | G39: BẦU NẤU THỊT BẰM | H39: MỒNG TƠI NẤU TÔM
B40: Trái cây | C40: TRÁI CÂY | D40: TRÁI CÂY | E40: TRÁI CÂY | F40: TRÁI CÂY | G40: TRÁI CÂY | H40: TRÁI CÂY
B43: MENU MẶN
B44: Món mặn 1 | C44: CÁ MỐI KHO RIM | D44: ĐÙI GÀ ROTY | E44: BÚN THỊT NƯỚNG | F44: CÁ NHÓI CHIÊN MẮM | G44: VỊT NẤU LAGU | H44: THỊT LUỘC MẮM NÊM
B45: Món mặn 2 | C45: MỰC CHIÊN MẮM | D45: TRỨNG LUỘC | F45: TÔM XÀO CHUA NGỌT | G45: CHẢ CÁ XÀO THƠM | H45: CÁ CHUỒN KẸP CHIÊN
B46: Rau | C46: CẢI NGỌT LUỘC | D46: CẢI CHUA XÀO | F46: MÍT NON XÀO | G46: RAU LANG LUỘC | H46: CÀ TÍM MỠ HÀNH
B47: Canh | C47: CANH CHUA | D47: BÍ ĐAO NẤU TÔM | F47: MỒNG TƠI NẤU TÔM | G47: BỒ NGÓT NẤU TÔM | H47: BẦU NẤU THỊT XAY
B48: Trái cây | C48: TRÁI CÂY | D48: TRÁI CÂY | E48: TRÁI CÂY | F48: TRÁI CÂY | G48: TRÁI CÂY | H48: TRÁI CÂY
B52: Menu suất ăn 34k
B55: MENU MẶN
...
